Workbook

Sheet Simple
A1: 017e2eb5-f076-4560-926c-2b59eed9b68f | B1: BPMN | C1: Confirm Coffee Preferences | D1: simple | E1: 18.19818 | F1: items,order | G1: true | H1: 16.633438 | I1: items,order | J1: false | K1: 13.622075 | L1: order | M1: false | N1: 28.204778 | O1: a1,a4,a7 | P1: true | Q1: 16.034109 | R1: No | S1: false | T1: CPEE | U1: Get Sun Data | V1: simple | W1: 89.795557 | X1: sunrise,sunset | Y1: false | Z1: 14.684785 | AA1: sunrise,sunset | AB1: false | AC1: 2.842104 | AD1: sunset | AE1: false | AF1: 2.435801 | AG1: a1,a2,a6 | AH1: false | AI1: 1.311049 | AJ1: Yes | AK1: true | AL1: Confirm Coffee Preferences | AM1: Get Sun Data | AN1: simple | AO1: 11.111347 | AP1: 2 | AQ1: 0 | AS1: =IF(AND(G1="true",J1="true",M1="true",P1="true",S1="true"),"true","false") -> false | AT1: =IF(AND(Y1="true",AB1="true",AE1="true",AH1="true",AK1="true"),"true","false") -> false
A2: 01f4a341-ea28-4399-a454-e817e931ace5 | B2: BPMN | C2: Get Sun Data | D2: simple | E2: 48.830044 | F2: sunrise,sunset | G2: false | H2: 21.877845 | I2: date | J2: true | K2: 11.49739 | L2: sunrise | M2: false | N2: 45.298577 | O2: a2,a5,a6 | P2: true | Q2: 103.6036 | R2: Yes | S2: false | T2: CPEE | U2: Confirm Coffee Preferences | V2: simple | W2: 27.210217 | Y2: false | Z2: 0.603523 | AB2: false | AC2: 0.538801 | AE2: false | AF2: 0.53049 | AH2: false | AI2: 1.407071 | AK2: false | AL2: Get Sun Data | AM2: Confirm Coffee Preferences | AN2: simple | AO2: 15.486164 | AS2: =IF(AND(G2="true",J2="true",M2="true",P2="true",S2="true"),"true","false") -> false | AT2: =IF(AND(Y2="true",AB2="true",AE2="true",AH2="true",AK2="true"),"true","false") -> false
A3: 034b22f4-ef21-405b-9772-5d5b7027bb0d | B3: BPMN | C3: Get Sun Data | D3: simple | E3: 78.290149 | F3: date,sunrise,sunset | G3: true | H3: 121.18928 | I3: date | J3: true | K3: 6.985788 | L3: sunrise,sunset | M3: true | N3: 48.513785 | O3: a2,a3,a5,a6 | P3: false | Q3: 47.606165 | R3: Yes | S3: false | T3: CPEE | U3: Confirm Coffee Preferences | V3: simple | W3: 111.01107 | X3: items,order | Y3: true | Z3: 18.17526 | AA3: order | AB3: true | AC3: 30.289332 | AD3: items,order | AE3: true | AF3: 41.362083 | AG3: a1,a4,a7 | AH3: true | AI3: 72.954892 | AJ3: Yes | AK3: false | AL3: Get Sun Data | AM3: Confirm Coffee Preferences | AN3: simple | AO3: 96.027494 | AP3: 0 | AQ3: 0 | AS3: =IF(AND(G3="true",J3="true",M3="true",P3="true",S3="true"),"true","false") -> false | AT3: =IF(AND(Y3="true",AB3="true",AE3="true",AH3="true",AK3="true"),"true","false") -> false
A4: 042ea4d3-a008-41ac-97dd-19a7f5dddedd | B4: BPMN | C4: Confirm Coffee Preferences | D4: simple | E4: 30.816763 | F4: emails,items,order | G4: false | H4: 19.803598 | I4: order | J4: true | K4: 6.380718 | L4: items,order | M4: true | N4: 20.029326 | O4: a1,a2,a4,a6,a7 | P4: false | Q4: 23.394127 | R4: No | S4: false | T4: CPEE | U4: Get Sun Data | V4: simple | W4: 20.229052 | X4: date,sunrise,sunset | Y4: true | Z4: 22.418518 | AA4: sunrise,sunset | AB4: false | AC4: 7.760213 | AD4: date | AE4: false | AF4: 25.688841 | AG4: a1,a2,a3,a4,a5,a6,a7,a8,a9 | AH4: false | AI4: 10.662069 | AJ4: Yes | AK4: true | AL4: Confirm Coffee Preferences | AM4: Get Sun Data | AN4: simple | AO4: 32.77256 | AP4: 0 | AQ4: 0 | AS4: =IF(AND(G4="true",J4="true",M4="true",P4="true",S4="true"),"true","false") -> false | AT4: =IF(AND(Y4="true",AB4="true",AE4="true",AH4="true",AK4="true"),"true","false") -> false
A5: 042fa867-804f-4712-a808-33c0a83be364 | B5: BPMN | C5: Confirm Coffee Preferences | D5: simple | E5: 54.115987 | F5: items,order | G5: true | H5: 17.465395 | I5: emails,items,refill | J5: false | K5: 24.712361 | L5: items,order | M5: true | N5: 29.20417 | O5: a1,a4,a7 | P5: true | Q5: 33.840706 | R5: No | S5: false | T5: CPEE | U5: Get Sun Data | V5: simple | W5: 104.2469 | X5: date,sunrise,sunset | Y5: true | Z5: 18.276466 | AA5: date | AB5: true | AC5: 11.92723 | AD5: sunrise,sunset | AE5: true | AF5: 48.012979 | AG5: a2,a3,a5,a6 | AH5: false | AI5: 8.318705 | AJ5: Yes | AK5: true | AL5: Confirm Coffee Preferences | AM5: Get Sun Data | AN5: simple | AO5: 28.826002 | AP5: 2 | AQ5: 0 | AS5: =IF(AND(G5="true",J5="true",M5="true",P5="true",S5="true"),"true","false") -> false | AT5: =IF(AND(Y5="true",AB5="true",AE5="true",AH5="true",AK5="true"),"true","false") -> false
A6: 04529132-49e2-4be8-9e17-b2afda1d83b2 | B6: BPMN | C6: Confirm Coffee Preferences | D6: simple | E6: 21.166265 | F6: items,order | G6: true | H6: 10.468402 | I6: items,order | J6: false | K6: 5.674582 | L6: order | M6: false | N6: 14.380275 | O6: a1,a4,a7 | P6: true | Q6: 19.96628 | R6: Yes | S6: false | T6: CPEE | U6: Get Sun Data | V6: simple | W6: 11.078657 | X6: hour,sunrise,sunset | Y6: false | Z6: 4.728545 | AA6: sunrise,sunset | AB6: false | AC6: 9.323602 | AD6: date | AE6: false | AF6: 9.716122 | AG6: a1,a3,a5,a7 | AH6: false | AI6: 13.177563 | AJ6: No | AK6: false | AL6: Confirm Coffee Preferences | AM6: Get Sun Data | AN6: simple | AO6: 31.004489 | AP6: 2 | AQ6: 0 | AR6: Diagramm did not load | AS6: =IF(AND(G6="true",J6="true",M6="true",P6="true",S6="true"),"true","false") -> false | AT6: =IF(AND(Y6="true",AB6="true",AE6="true",AH6="true",AK6="true"),"true","false") -> false
A7: 08de56d6-e9d8-4280-9779-f5fea9727ec0 | B7: BPMN | C7: Confirm Coffee Preferences | D7: simple | E7: 8.865678 | F7: order | G7: false | H7: 10.916101 | I7: order | J7: true | K7: 7.02223 | L7: items,order | M7: true | N7: 11.95172 | O7: a6,a7 | P7: false | Q7: 29.234533 | R7: No | S7: false | T7: CPEE | U7: Get Sun Data | V7: simple | W7: 14.080474 | X7: date,hour,sunrise,sunset | Y7: false | Z7: 9.473922 | AA7: date | AB7: true | AC7: 6.675165 | AD7: sunrise,sunset | AE7: true | AF7: 26.181035 | AG7: a2,a5,a6 | AH7: true | AI7: 6.086983 | AJ7: Yes | AK7: true | AL7: Confirm Coffee Preferences | AM7: Get Sun Data | AN7: simple | AO7: 14.595567 | AP7: -1 | AQ7: 1 | AS7: =IF(AND(G7="true",J7="true",M7="true",P7="true",S7="true"),"true","false") -> false | AT7: =IF(AND(Y7="true",AB7="true",AE7="true",AH7="true",AK7="true"),"true","false") -> false
A8: 0a0f4419-1682-47df-bf40-7214c90b09c0 | B8: BPMN | C8: Confirm Coffee Preferences | D8: simple | E8: 14.609313 | F8: items,order | G8: true | H8: 9.440073 | I8: items,order | J8: false | K8: 12.242627 | L8: items,order | M8: true | N8: 16.695539 | O8: a1,a4,a7 | P8: true | Q8: 18.89221 | R8: No | S8: false | T8: CPEE | U8: Get Sun Data | V8: simple | W8: 32.883826 | X8: date,sunrise,sunset | Y8: true | Z8: 9.476277 | AA8: sunrise,sunset | AB8: false | AC8: 4.030773 | AD8: date | AE8: false | AF8: 25.486955 | AG8: a2,a5,a6 | AH8: true | AI8: 18.122844 | AJ8: Yes | AK8: true | AL8: Confirm Coffee Preferences | AM8: Get Sun Data | AN8: simple | AO8: 12.825459 | AP8: 2 | AQ8: 1 | AS8: =IF(AND(G8="true",J8="true",M8="true",P8="true",S8="true"),"true","false") -> false | AT8: =IF(AND(Y8="true",AB8="true",AE8="true",AH8="true",AK8="true"),"true","false") -> false
A9: 0c0a1744-da50-4b2a-a32e-bdbcb293c127 | B9: BPMN | C9: Get Sun Data | D9: simple | E9: 10.755159 | F9: date,sunrise,sunset | G9: true | H9: 14.472332 | I9: date | J9: true | K9: 4.313003 | L9: sunrise,sunset | M9: true | N9: 22.63504 | O9: a2,a3,a5,a6 | P9: false | Q9: 31.26741 | R9: No | S9: false | T9: CPEE | U9: Confirm Coffee Preferences | V9: simple | W9: 32.987542 | X9: items,order | Y9: true | Z9: 11.036902 | AA9: items,order | AB9: false | AC9: 9.401149 | AD9: items,order | AE9: true | AF9: 32.33137 | AG9: a1,a4,a7 | AH9: true | AI9: 14.545325 | AJ9: Yes | AK9: false | AL9: Get Sun Data | AM9: Confirm Coffee Preferences | AN9: simple | AO9: 11.131242 | AP9: 1 | AQ9: 0 | AS9: =IF(AND(G9="true",J9="true",M9="true",P9="true",S9="true"),"true","false") -> false | AT9: =IF(AND(Y9="true",AB9="true",AE9="true",AH9="true",AK9="true"),"true","false") -> false
A10: 0dcaa55e-38ae-428e-a1c1-b378cb31a99c | B10: BPMN | C10: Get Sun Data | D10: simple | E10: 27.86635 | F10: date,sunrise,sunset | G10: true | H10: 33.803115 | I10: date | J10: true | K10: 4.508574 | L10: sunrise,sunset | M10: true | N10: 66.278391 | O10: a2,a3,a5,a6 | P10: false | Q10: 62.54033 | R10: Yes | S10: false | T10: CPEE | U10: Confirm Coffee Preferences | V10: simple | W10: 49.091361 | X10: emails,items,order,refill | Y10: false | Z10: 73.073432 | AA10: emails,refill | AB10: false | AC10: 0.334399 | AE10: false | AF10: 76.510411 | AG10: a1,a4,a7 | AH10: true | AI10: 6.921414 | AJ10: Yes | AK10: false | AL10: Get Sun Data | AM10: Confirm Coffee Preferences | AN10: simple | AO10: 16.060695 | AP10: 1 | AQ10: 1 | AS10: =IF(AND(G10="true",J10="true",M10="true",P10="true",S10="true"),"true","false") -> false | AT10: =IF(AND(Y10="true",AB10="true",AE10="true",AH10="true",AK10="true"),"true","false") -> false
A11: 0f0b0d0d-232b-4957-8db8-43cdb8f4c197 | B11: BPMN | C11: Confirm Coffee Preferences | D11: simple | E11: 27.15559 | F11: items,order | G11: true | H11: 10.825807 | I11: order | J11: true | K11: 11.250723 | L11: items,order | M11: true | N11: 30.462786 | O11: a1,a4,a7 | P11: true | Q11: 14.6125 | R11: No | S11: false | T11: CPEE | U11: Get Sun Data | V11: simple | W11: 42.062175 | X11: date,sunrise,sunset | Y11: true | Z11: 16.131163 | AA11: sunrise,sunset | AB11: false | AC11: 7.985978 | AD11: date | AE11: false | AF11: 49.327833 | AG11: a2,a5,a6 | AH11: true | AI11: 16.113462 | AJ11: Yes | AK11: true | AL11: Confirm Coffee Preferences | AM11: Get Sun Data | AN11: simple | AO11: 85.196854 | AP11: 1 | AQ11: 1 | AR11: No i don't | AS11: =IF(AND(G11="true",J11="true",M11="true",P11="true",S11="true"),"true","false") -> false | AT11: =IF(AND(Y11="true",AB11="true",AE11="true",AH11="true",AK11="true"),"true","false") -> false
A12: 11089388-175e-4194-972f-a9f835a1aad0 | B12: BPMN | C12: Confirm Coffee Preferences | D12: simple | E12: 18.159608 | F12: items,order | G12: true | H12: 18.669652 | I12: order | J12: true | K12: 13.298763 | L12: items,order | M12: true | N12: 38.773545 | O12: a1,a4,a7 | P12: true | Q12: 17.935423 | R12: No | S12: false | T12: CPEE | U12: Get Sun Data | V12: simple | W12: 16.917137 | X12: date,sunrise,sunset | Y12: true | Z12: 30.237329 | AA12: sunrise,sunset | AB12: false | AC12: 5.467975 | AD12: date | AE12: false | AF12: 30.02539 | AG12: a5,a6 | AH12: false | AI12: 15.100483 | AJ12: Yes | AK12: true | AL12: Confirm Coffee Preferences | AM12: Get Sun Data | AN12: simple | AO12: 55.10876 | AP12: 1 | AQ12: 1 | AS12: =IF(AND(G12="true",J12="true",M12="true",P12="true",S12="true"),"true","false") -> false | AT12: =IF(AND(Y12="true",AB12="true",AE12="true",AH12="true",AK12="true"),"true","false") -> false
A13: 12ed4e88-2347-4683-a8f3-1b192ff38aa9 | B13: BPMN | C13: Get Sun Data | D13: simple | E13: 16.123896 | F13: date,sunrise,sunset | G13: true | H13: 12.414197 | I13: date | J13: true | K13: 6.916093 | L13: sunrise,sunset | M13: true | N13: 33.789112 | O13: a5,a6 | P13: false | Q13: 16.228512 | R13: Yes | S13: false | T13: CPEE | U13: Confirm Coffee Preferences | V13: simple | W13: 28.160084 | X13: items | Y13: false | Z13: 28.492034 | AA13: order | AB13: true | AC13: 19.027993 | AD13: items | AE13: false | AF13: 20.605501 | AG13: a1 | AH13: false | AI13: 18.629612 | AJ13: Yes | AK13: false | AL13: Get Sun Data | AM13: Confirm Coffee Preferences | AN13: simple | AO13: 12.08933 | AP13: 0 | AQ13: 0 | AS13: =IF(AND(G13="true",J13="true",M13="true",P13="true",S13="true"),"true","false") -> false | AT13: =IF(AND(Y13="true",AB13="true",AE13="true",AH13="true",AK13="true"),"true","false") -> false
A14: 16d8b8fa-d529-4c81-986c-f92981d9b7cc | B14: BPMN | C14: Confirm Coffee Preferences | D14: simple | E14: 24.420656 | F14: items,order | G14: true | H14: 14.669546 | I14: order | J14: true | K14: 8.727071 | L14: items,order | M14: true | N14: 22.868123 | O14: a1 | P14: false | Q14: 32.682112 | R14: No | S14: false | T14: CPEE | U14: Get Sun Data | V14: simple | W14: 15.904146 | X14: date,sunrise,sunset | Y14: true | Z14: 33.974774 | AA14: date | AB14: true | AC14: 5.81821 | AD14: sunrise,sunset | AE14: true | AF14: 43.815933 | AG14: a2,a3,a5,a6 | AH14: false | AI14: 14.521968 | AJ14: Yes | AK14: true | AL14: Confirm Coffee Preferences | AM14: Get Sun Data | AN14: simple | AO14: 73.36014 | AP14: 2 | AQ14: 0 | AR14: I forgot which arrow represents writes and which reads. | AS14: =IF(AND(G14="true",J14="true",M14="true",P14="true",S14="true"),"true","false") -> false | AT14: =IF(AND(Y14="true",AB14="true",AE14="true",AH14="true",AK14="true"),"true","false") -> false
A15: 1765c273-7922-4e11-bd34-8935ee015fd5 | B15: BPMN | C15: Confirm Coffee Preferences | D15: simple | E15: 752.1742 | F15: items,order | G15: true | H15: 8.519093 | I15: order | J15: true | K15: 8.446703 | L15: items,order | M15: true | N15: 12.319297 | O15: a1,a4,a7 | P15: true | Q15: 7.754247 | R15: I cant be sure | S15: true | T15: CPEE | U15: Get Sun Data | V15: simple | W15: 10.846408 | X15: date,sunrise,sunset | Y15: true | Z15: 7.300833 | AA15: date | AB15: true | AC15: 8.135384 | AD15: sunrise,sunset | AE15: true | AF15: 23.103903 | AG15: a2,a5,a6 | AH15: true | AI15: 2.071143 | AJ15: Yes | AK15: true | AL15: Confirm Coffee Preferences | AM15: Get Sun Data | AN15: simple | AO15: 12.068401 | AP15: 1 | AQ15: 2 | AR15: Nope | AS15: =IF(AND(G15="true",J15="true",M15="true",P15="true",S15="true"),"true","false") -> true | AT15: =IF(AND(Y15="true",AB15="true",AE15="true",AH15="true",AK15="true"),"true","false") -> true
A16: 18104a50-6d19-4dbd-9f6a-70e4f4bf52c4 | B16: BPMN | C16: Confirm Coffee Preferences | D16: simple | E16: 22.329356 | F16: items,order | G16: true | H16: 12.68665 | I16: order | J16: true | K16: 7.051665 | L16: items,order | M16: true | N16: 18.998948 | O16: a1,a4,a7 | P16: true | Q16: 17.156473 | R16: Yes | S16: false | T16: CPEE | U16: Get Sun Data | V16: simple | W16: 25.950689 | X16: date,sunrise,sunset | Y16: true | Z16: 13.642854 | AA16: date | AB16: true | AC16: 9.426851 | AD16: sunrise,sunset | AE16: true | AF16: 29.397643 | AG16: a2,a3,a5,a6 | AH16: false | AI16: 12.167432 | AJ16: Yes | AK16: true | AL16: Confirm Coffee Preferences | AM16: Get Sun Data | AN16: simple | AO16: 7.567719 | AP16: 2 | AQ16: 1 | AS16: =IF(AND(G16="true",J16="true",M16="true",P16="true",S16="true"),"true","false") -> false | AT16: =IF(AND(Y16="true",AB16="true",AE16="true",AH16="true",AK16="true"),"true","false") -> false
A17: 195cb5db-d09b-4876-9da8-d3f19b5851c8 | B17: BPMN | C17: Confirm Coffee Preferences | D17: simple | E17: 14.366735 | F17: items,order | G17: true | H17: 7.526705 | I17: order | J17: true | K17: 2.577106 | L17: items,order | M17: true | N17: 16.892631 | O17: a1,a4,a7 | P17: true | Q17: 9.218188 | R17: No | S17: false | T17: CPEE | U17: Get Sun Data | V17: simple | W17: 13.915979 | X17: date,sunrise,sunset | Y17: true | Z17: 6.827948 | AA17: date | AB17: true | AC17: 6.015879 | AD17: sunrise,sunset | AE17: true | AF17: 24.638148 | AG17: a2,a3,a5,a6 | AH17: false | AI17: 5.086044 | AJ17: Yes | AK17: true | AL17: Confirm Coffee Preferences | AM17: Get Sun Data | AN17: simple | AO17: 26.340224 | AP17: 1 | AQ17: 2 | AS17: =IF(AND(G17="true",J17="true",M17="true",P17="true",S17="true"),"true","false") -> false | AT17: =IF(AND(Y17="true",AB17="true",AE17="true",AH17="true",AK17="true"),"true","false") -> false
A18: 19f2e5f2-65b8-4cef-8a1c-399e4c41baaf | B18: BPMN | C18: Confirm Coffee Preferences | D18: simple | E18: 36.417236 | F18: items,order | G18: true | H18: 35.544207 | I18: items,order | J18: false | K18: 17.580112 | L18: items,order | M18: true | N18: 19.030605 | O18: a1,a4,a7 | P18: true | Q18: 27.898287 | R18: Yes | S18: false | T18: CPEE | U18: Get Sun Data | V18: simple | W18: 29.60218 | X18: date | Y18: false | Z18: 1.020157 | AA18: hour | AB18: false | AC18: 0.869164 | AD18: sunrise | AE18: false | AF18: 2.73235 | AG18: a2,a5,a6 | AH18: true | AI18: 2.448802 | AJ18: Yes | AK18: true | AL18: Confirm Coffee Preferences | AM18: Get Sun Data | AN18: simple | AO18: 5.680848 | AP18: 1 | AQ18: 1 | AS18: =IF(AND(G18="true",J18="true",M18="true",P18="true",S18="true"),"true","false") -> false | AT18: =IF(AND(Y18="true",AB18="true",AE18="true",AH18="true",AK18="true"),"true","false") -> false
A19: 1e8ee981-3bc2-497c-a7ef-7fba32865218 | B19: BPMN | C19: Get Sun Data | D19: simple | E19: 18.740801 | F19: date,sunrise,sunset | G19: true | H19: 13.346525 | I19: date | J19: true | K19: 6.192337 | L19: sunrise,sunset | M19: true | N19: 46.003915 | O19: a2,a5,a6 | P19: true | Q19: 48.507488 | R19: No | S19: false | T19: CPEE | U19: Confirm Coffee Preferences | V19: simple | W19: 50.735037 | X19: items,order | Y19: true | Z19: 13.838046 | AA19: order | AB19: true | AC19: 7.275739 | AD19: items,order | AE19: true | AF19: 17.757176 | AG19: a1,a4,a7 | AH19: true | AI19: 37.857388 | AJ19: Yes | AK19: false | AL19: Get Sun Data | AM19: Confirm Coffee Preferences | AN19: simple | AO19: 17.865319 | AP19: 1 | AQ19: 0 | AS19: =IF(AND(G19="true",J19="true",M19="true",P19="true",S19="true"),"true","false") -> false | AT19: =IF(AND(Y19="true",AB19="true",AE19="true",AH19="true",AK19="true"),"true","false") -> false
A20: 1fb06626-ce2a-43ac-a3e9-adb886507041 | B20: BPMN | C20: Get Sun Data | D20: simple | E20: 22.388168 | F20: sunrise,sunset | G20: false | H20: 10.800945 | I20: date | J20: true | K20: 30.256338 | L20: sunrise,sunset | M20: true | N20: 45.12651 | O20: a2,a3,a5,a6 | P20: false | Q20: 52.897321 | R20: No | S20: false | T20: CPEE | U20: Confirm Coffee Preferences | V20: simple | W20: 44.315932 | X20: items,order | Y20: true | Z20: 13.415693 | AA20: order | AB20: true | AC20: 5.792744 | AD20: items | AE20: false | AF20: 28.682819 | AG20: a1,a4,a7 | AH20: true | AI20: 52.301244 | AJ20: Yes | AK20: false | AL20: Get Sun Data | AM20: Confirm Coffee Preferences | AN20: simple | AO20: 7.451917 | AP20: 1 | AQ20: 1 | AS20: =IF(AND(G20="true",J20="true",M20="true",P20="true",S20="true"),"true","false") -> false | AT20: =IF(AND(Y20="true",AB20="true",AE20="true",AH20="true",AK20="true"),"true","false") -> false
A21: 21d06c9a-e06b-4908-98bf-38035ad47b4f | B21: BPMN | C21: Confirm Coffee Preferences | D21: simple | E21: 10.646109 | F21: items,order | G21: true | H21: 4.943961 | I21: order | J21: true | K21: 6.237828 | L21: items,order | M21: true | N21: 13.684033 | O21: a1,a4,a7 | P21: true | Q21: 6.779193 | R21: No | S21: false | T21: CPEE | U21: Get Sun Data | V21: simple | W21: 21.745252 | X21: date,sunrise,sunset | Y21: true | Z21: 11.674666 | AA21: sunrise,sunset | AB21: false | AC21: 8.359973 | AD21: sunrise,sunset | AE21: true | AF21: 22.037178 | AG21: a1,a2,a3,a4,a5,a6,a7,a8,a9 | AH21: false | AI21: 17.504379 | AJ21: I cant be sure | AK21: false | AL21: Confirm Coffee Preferences | AM21: Get Sun Data | AN21: simple | AO21: 63.752344 | AP21: 2 | AQ21: -1 | AR21: The small arrows and many bars, while effective for easier models, become more difficult to read quickly for people with less experience using CPEE BPMN. | AS21: =IF(AND(G21="true",J21="true",M21="true",P21="true",S21="true"),"true","false") -> false | AT21: =IF(AND(Y21="true",AB21="true",AE21="true",AH21="true",AK21="true"),"true","false") -> false
A22: 25358758-6f87-4398-b82c-122106e5fabd | B22: BPMN | C22: Get Sun Data | D22: simple | E22: 28.774966 | F22: date,sunrise,sunset | G22: true | H22: 35.036527 | I22: date | J22: true | K22: 7.267438 | L22: sunrise,sunset | M22: true | N22: 48.283308 | O22: a2,a3,a5,a6 | P22: false | Q22: 16.87505 | R22: Yes | S22: false | T22: CPEE | U22: Confirm Coffee Preferences | V22: simple | W22: 95.151615 | X22: emails,refill | Y22: false | Z22: 29.687575 | AA22: emails,refill | AB22: false | AC22: 15.5549 | AE22: false | AF22: 47.285457 | AG22: a1,a4,a6,a7 | AH22: false | AI22: 19.800807 | AJ22: Yes | AK22: false | AL22: Get Sun Data | AM22: Confirm Coffee Preferences | AN22: simple | AO22: 52.416944 | AP22: 1 | AQ22: 0 | AR22: Man musste erst drauf kommen, wie es funktioniert. Gerne Ã¶fters solche Ãbungen, die sind top!! Helfen einem super, das zu verstehen und macht echt SpaÃ. | AS22: =IF(AND(G22="true",J22="true",M22="true",P22="true",S22="true"),"true","false") -> false | AT22: =IF(AND(Y22="true",AB22="true",AE22="true",AH22="true",AK22="true"),"true","false") -> false
A23: 2658a615-10ed-4079-847c-130becd6377f | B23: BPMN | C23: Confirm Coffee Preferences | D23: simple | E23: 35.451832 | F23: order | G23: false | H23: 21.175062 | I23: order | J23: true | K23: 11.327226 | L23: items | M23: false | N23: 12.513529 | O23: a1 | P23: false | Q23: 21.769395 | R23: No | S23: false | T23: CPEE | U23: Get Sun Data | V23: simple | W23: 42.78727 | X23: sunset | Y23: false | Z23: 19.674993 | AA23: date | AB23: true | AC23: 11.477926 | AD23: sunrise | AE23: false | AF23: 23.089712 | AG23: a2 | AH23: false | AI23: 16.975039 | AJ23: Yes | AK23: true | AL23: Confirm Coffee Preferences | AM23: Get Sun Data | AN23: simple | AO23: 44.996866 | AP23: -1 | AQ23: -1 | AR23: Understanding the interconnections between read and write operations from a graphical standpoint. | AS23: =IF(AND(G23="true",J23="true",M23="true",P23="true",S23="true"),"true","false") -> false | AT23: =IF(AND(Y23="true",AB23="true",AE23="true",AH23="true",AK23="true"),"true","false") -> false
A24: 279d674a-b893-47f9-92ec-d162aa37f045 | B24: BPMN | C24: Confirm Coffee Preferences | D24: simple | E24: 14.407375 | F24: order | G24: false | H24: 19.262887 | I24: items,order | J24: false | K24: 11.656385 | L24: items,order | M24: true | N24: 10.932594 | O24: a1 | P24: false | Q24: 10.870609 | R24: Yes | S24: false | T24: CPEE | U24: Get Sun Data | V24: simple | W24: 10.875191 | X24: sunrise | Y24: false | Z24: 20.714458 | AA24: sunrise,sunset | AB24: false | AC24: 14.451549 | AD24: hour | AE24: false | AF24: 14.15916 | AG24: a1 | AH24: false | AI24: 5.393828 | AJ24: Yes | AK24: true | AL24: Confirm Coffee Preferences | AM24: Get Sun Data | AN24: simple | AO24: 33.352216 | AP24: 1 | AQ24: -1 | AR24: It is not loading on safari | AS24: =IF(AND(G24="true",J24="true",M24="true",P24="true",S24="true"),"true","false") -> false | AT24: =IF(AND(Y24="true",AB24="true",AE24="true",AH24="true",AK24="true"),"true","false") -> false
A25: 28bd6c19-f114-4eb1-b43f-ed5bbcd2a685 | B25: BPMN | C25: Get Sun Data | D25: simple | E25: 27.268039 | F25: date,sunrise,sunset | G25: true | H25: 8.484017 | I25: date,sunrise,sunset | J25: false | K25: 17.589809 | L25: sunrise,sunset | M25: true | N25: 32.569759 | O25: a1,a2,a8 | P25: false | Q25: 16.17566 | R25: Yes | S25: false | T25: CPEE | U25: Confirm Coffee Preferences | V25: simple | W25: 449.78777 | X25: items,order | Y25: true | Z25: 12.412584 | AB25: false | AC25: 9.641798 | AD25: items | AE25: false | AF25: 15.253813 | AG25: a1,a6 | AH25: false | AI25: 18.279274 | AJ25: No | AK25: true | AL25: Get Sun Data | AM25: Confirm Coffee Preferences | AN25: simple | AO25: 13.309408 | AP25: -1 | AQ25: 1 | AS25: =IF(AND(G25="true",J25="true",M25="true",P25="true",S25="true"),"true","false") -> false | AT25: =IF(AND(Y25="true",AB25="true",AE25="true",AH25="true",AK25="true"),"true","false") -> false
A26: 2bc2639c-b3e2-4386-b3e6-032c6a6092e0 | B26: BPMN | C26: Confirm Coffee Preferences | D26: simple | E26: 28.65092 | F26: items,order | G26: true | H26: 11.32238 | I26: order | J26: true | K26: 6.785097 | L26: items,order | M26: true | N26: 22.614474 | O26: a1,a4,a7 | P26: true | Q26: 48.603064 | R26: No | S26: false | T26: CPEE | U26: Get Sun Data | V26: simple | W26: 21.021396 | X26: date,sunrise,sunset | Y26: true | Z26: 22.15392 | AA26: date | AB26: true | AC26: 8.278128 | AD26: sunrise,sunset | AE26: true | AF26: 28.779176 | AG26: a2,a5,a6 | AH26: true | AI26: 30.691077 | AJ26: Yes | AK26: true | AL26: Confirm Coffee Preferences | AM26: Get Sun Data | AN26: simple | AO26: 97.290671 | AP26: 0 | AQ26: 1 | AR26: CEEP is more difficult to understand the diagramm as a hole but more easy to find specifics. | AS26: =IF(AND(G26="true",J26="true",M26="true",P26="true",S26="true"),"true","false") -> false | AT26: =IF(AND(Y26="true",AB26="true",AE26="true",AH26="true",AK26="true"),"true","false") -> true
A27: 2cd942ac-a421-4fd0-9ef5-29f230bbb996 | B27: BPMN | C27: Get Sun Data | D27: simple | E27: 24.457484 | F27: date,sunrise,sunset | G27: true | H27: 21.707864 | I27: date | J27: true | K27: 6.426139 | L27: sunrise,sunset | M27: true | N27: 29.576189 | O27: a2,a3,a5,a6 | P27: false | Q27: 34.896346 | R27: No | S27: false | T27: CPEE | U27: Confirm Coffee Preferences | V27: simple | W27: 41.712371 | X27: items,order | Y27: true | Z27: 21.297854 | AA27: order | AB27: true | AC27: 11.409629 | AD27: items,order | AE27: true | AF27: 32.266786 | AG27: a4 | AH27: false | AI27: 40.07122 | AJ27: I cant be sure | AK27: false | AL27: Get Sun Data | AM27: Confirm Coffee Preferences | AN27: simple | AO27: 30.397876 | AP27: 2 | AQ27: -2 | AS27: =IF(AND(G27="true",J27="true",M27="true",P27="true",S27="true"),"true","false") -> false | AT27: =IF(AND(Y27="true",AB27="true",AE27="true",AH27="true",AK27="true"),"true","false") -> false
A28: 2ef4cfbb-c311-4acd-a615-9c3d2a1b21bb | B28: BPMN | C28: Get Sun Data | D28: simple | E28: 16.784983 | F28: sunrise,sunset | G28: false | H28: 6.087746 | I28: date | J28: true | K28: 5.50984 | L28: sunrise,sunset | M28: true | N28: 24.384853 | O28: a2,a5,a6 | P28: true | Q28: 26.502595 | R28: Yes | S28: false | T28: CPEE | U28: Confirm Coffee Preferences | V28: simple | W28: 38.012643 | X28: items,order | Y28: true | Z28: 22.893523 | AA28: items | AB28: false | AC28: 3.755848 | AE28: false | AF28: 35.50933 | AG28: a1,a4,a7 | AH28: true | AI28: 17.253133 | AJ28: Yes | AK28: false | AL28: Get Sun Data | AM28: Confirm Coffee Preferences | AN28: simple | AO28: 11.611721 | AP28: 1 | AQ28: 0 | AS28: =IF(AND(G28="true",J28="true",M28="true",P28="true",S28="true"),"true","false") -> false | AT28: =IF(AND(Y28="true",AB28="true",AE28="true",AH28="true",AK28="true"),"true","false") -> false
A29: 30e44ca2-097d-4b68-b090-6b57b525c3ae | B29: BPMN | C29: Confirm Coffee Preferences | D29: simple | E29: 27.950299 | F29: items,order | G29: true | H29: 21.728274 | I29: order | J29: true | K29: 9.716066 | L29: items,order | M29: true | N29: 27.928232 | O29: a1,a4,a7 | P29: true | Q29: 31.738011 | R29: Yes | S29: false | T29: CPEE | U29: Get Sun Data | V29: simple | W29: 26.984346 | X29: date,sunrise,sunset | Y29: true | Z29: 18.299009 | AA29: date | AB29: true | AC29: 10.813249 | AD29: sunrise,sunset | AE29: true | AF29: 60.869896 | AG29: a2,a3,a5,a6 | AH29: false | AI29: 19.989385 | AJ29: Yes | AK29: true | AL29: Confirm Coffee Preferences | AM29: Get Sun Data | AN29: simple | AO29: 55.422463 | AP29: 2 | AQ29: 2 | AS29: =IF(AND(G29="true",J29="true",M29="true",P29="true",S29="true"),"true","false") -> false | AT29: =IF(AND(Y29="true",AB29="true",AE29="true",AH29="true",AK29="true"),"true","false") -> false
A30: 31dcf553-e3d2-4a55-b773-d524c37dd2a4 | B30: BPMN | C30: Confirm Coffee Preferences | D30: simple | E30: 56.045402 | F30: items,order | G30: true | H30: 38.306199 | I30: items,order | J30: false | K30: 16.809225 | L30: items,order | M30: true | N30: 23.651339 | O30: a1,a4,a7 | P30: true | Q30: 15.367342 | R30: No | S30: false | T30: CPEE | U30: Get Sun Data | V30: simple | W30: 76.918524 | X30: date,sunrise,sunset | Y30: true | Z30: 8.101647 | AA30: sunrise,sunset | AB30: false | AC30: 1.915537 | AD30: date | AE30: false | AF30: 35.35379 | AG30: a2,a3,a5,a6 | AH30: false | AI30: 36.457945 | AJ30: I cant be sure | AK30: false | AL30: Confirm Coffee Preferences | AM30: Get Sun Data | AN30: simple | AO30: 9.134926 | AP30: 1 | AQ30: 0 | AS30: =IF(AND(G30="true",J30="true",M30="true",P30="true",S30="true"),"true","false") -> false | AT30: =IF(AND(Y30="true",AB30="true",AE30="true",AH30="true",AK30="true"),"true","false") -> false
A31: 32ed680e-7751-4fe6-b93b-d03ea58809ef | B31: BPMN | C31: Confirm Coffee Preferences | D31: simple | E31: 16.649711 | F31: items,order | G31: true | H31: 10.796034 | I31: items,order | J31: false | K31: 7.571309 | L31: items,order | M31: true | N31: 24.483461 | O31: a1,a4,a7 | P31: true | Q31: 71.234436 | R31: Yes | S31: false | T31: CPEE | U31: Get Sun Data | V31: simple | W31: 34.114345 | X31: date,sunrise,sunset | Y31: true | Z31: 23.557913 | AA31: date | AB31: true | AC31: 12.660496 | AD31: sunrise,sunset | AE31: true | AF31: 57.260799 | AG31: a2,a5,a6 | AH31: true | AI31: 5.721019 | AJ31: Yes | AK31: true | AL31: Confirm Coffee Preferences | AM31: Get Sun Data | AN31: simple | AO31: 17.517797 | AP31: 1 | AQ31: 1 | AS31: =IF(AND(G31="true",J31="true",M31="true",P31="true",S31="true"),"true","false") -> false | AT31: =IF(AND(Y31="true",AB31="true",AE31="true",AH31="true",AK31="true"),"true","false") -> true
A32: 38d25a54-c191-40b6-aa37-7dc785a46a50 | B32: BPMN | C32: Confirm Coffee Preferences | D32: simple | E32: 27.730996 | F32: items,order | G32: true | H32: 17.394532 | I32: refill | J32: false | K32: 14.583827 | L32: emails | M32: false | N32: 106.04564 | O32: a7 | P32: false | Q32: 13.849818 | R32: No | S32: false | T32: CPEE | U32: Get Sun Data | V32: simple | W32: 64.838903 | X32: date,sunrise,sunset | Y32: true | Z32: 16.971175 | AA32: date | AB32: true | AC32: 79.728025 | AD32: sunrise,sunset | AE32: true | AF32: 65.951112 | AG32: a2,a3,a5,a6 | AH32: false | AI32: 36.421949 | AJ32: I cant be sure | AK32: false | AL32: Confirm Coffee Preferences | AM32: Get Sun Data | AN32: simple | AO32: 23.649695 | AP32: 0 | AQ32: 1 | AS32: =IF(AND(G32="true",J32="true",M32="true",P32="true",S32="true"),"true","false") -> false | AT32: =IF(AND(Y32="true",AB32="true",AE32="true",AH32="true",AK32="true"),"true","false") -> false
A33: 39a66cba-bbc6-4fd0-b8f5-5b2b6e4046f7 | B33: BPMN | C33: Confirm Coffee Preferences | D33: simple | E33: 17.620758 | F33: items,order | G33: true | H33: 19.566508 | I33: items,order | J33: false | K33: 13.050822 | L33: items,order | M33: true | N33: 22.943715 | O33: a1,a4,a7 | P33: true | Q33: 23.252404 | R33: Yes | S33: false | T33: CPEE | U33: Get Sun Data | V33: simple | W33: 19.583085 | X33: date,sunrise,sunset | Y33: true | Z33: 10.889121 | AA33: sunrise,sunset | AB33: false | AC33: 6.570853 | AD33: date | AE33: false | AF33: 28.713616 | AG33: a2,a5,a6 | AH33: true | AI33: 6.8013 | AJ33: Yes | AK33: true | AL33: Confirm Coffee Preferences | AM33: Get Sun Data | AN33: simple | AO33: 14.861549 | AP33: -1 | AQ33: 2 | AS33: =IF(AND(G33="true",J33="true",M33="true",P33="true",S33="true"),"true","false") -> false | AT33: =IF(AND(Y33="true",AB33="true",AE33="true",AH33="true",AK33="true"),"true","false") -> false
A34: 39b10480-d4c8-4e1f-831f-bc4b0fcf3ff6 | B34: BPMN | C34: Get Sun Data | D34: simple | E34: 15.376944 | F34: date | G34: false | H34: 18.296733 | I34: date | J34: true | K34: 10.533409 | L34: sunrise,sunset | M34: true | N34: 29.956139 | O34: a2,a5,a6 | P34: true | Q34: 10.309922 | R34: Yes | S34: false | T34: CPEE | U34: Confirm Coffee Preferences | V34: simple | W34: 20.834354 | X34: refill | Y34: false | Z34: 25.564085 | AA34: order | AB34: true | AC34: 8.657717 | AD34: items,order | AE34: true | AF34: 26.923809 | AG34: a1,a4,a7 | AH34: true | AI34: 16.7842 | AJ34: No | AK34: true | AL34: Get Sun Data | AM34: Confirm Coffee Preferences | AN34: simple | AO34: 12.0409 | AP34: 0 | AQ34: 0 | AS34: =IF(AND(G34="true",J34="true",M34="true",P34="true",S34="true"),"true","false") -> false | AT34: =IF(AND(Y34="true",AB34="true",AE34="true",AH34="true",AK34="true"),"true","false") -> false
A35: 3ba490ae-a764-44e3-9834-ae0472f1f4c6 | B35: BPMN | C35: Get Sun Data | D35: simple | E35: 34.144296 | F35: date,sunrise,sunset | G35: true | H35: 42.656212 | I35: sunrise,sunset | J35: false | K35: 21.766601 | L35: sunrise,sunset | M35: true | N35: 32.97592 | O35: a2,a3,a5,a6 | P35: false | Q35: 21.927825 | R35: Yes | S35: false | T35: CPEE | U35: Confirm Coffee Preferences | V35: simple | W35: 33.353897 | X35: items,order | Y35: true | Z35: 29.506506 | AA35: order | AB35: true | AC35: 7.632978 | AD35: items,order | AE35: true | AF35: 23.798868 | AG35: a1,a4,a7 | AH35: true | AI35: 14.157586 | AJ35: Yes | AK35: false | AL35: Get Sun Data | AM35: Confirm Coffee Preferences | AN35: simple | AO35: 75.983997 | AP35: 1 | AQ35: 0 | AR35: Im Grunde muss ich nur noch sicherer im Umgang mit beiden werden, auf das CPEE BPMN ist auf den ersten Blick unÃ¼bersichtlicher und erfordert minimal mehr grundverstÃ¤ndnis | AS35: =IF(AND(G35="true",J35="true",M35="true",P35="true",S35="true"),"true","false") -> false | AT35: =IF(AND(Y35="true",AB35="true",AE35="true",AH35="true",AK35="true"),"true","false") -> false
A36: 3f592c91-d28f-447f-bc9b-ead3b892754d | B36: BPMN | C36: Get Sun Data | D36: simple | E36: 24.588679 | F36: date,sunrise,sunset | G36: true | H36: 12.320244 | I36: date | J36: true | K36: 3.66871 | L36: sunrise,sunset | M36: true | N36: 31.717793 | O36: a2,a3,a5,a6 | P36: false | Q36: 36.006787 | R36: Yes | S36: false | T36: CPEE | U36: Confirm Coffee Preferences | V36: simple | W36: 39.703684 | X36: items,order | Y36: true | Z36: 15.266323 | AA36: items,order | AB36: false | AC36: 9.090807 | AD36: order | AE36: false | AF36: 20.376043 | AG36: a1,a4,a7 | AH36: true | AI36: 21.969078 | AJ36: No | AK36: true | AL36: Get Sun Data | AM36: Confirm Coffee Preferences | AN36: simple | AO36: 64.073921 | AP36: 1 | AQ36: 1 | AS36: =IF(AND(G36="true",J36="true",M36="true",P36="true",S36="true"),"true","false") -> false | AT36: =IF(AND(Y36="true",AB36="true",AE36="true",AH36="true",AK36="true"),"true","false") -> false
A37: 40fc4049-2873-4051-827f-6a0413989c8c | B37: BPMN | C37: Confirm Coffee Preferences | D37: simple | E37: 39.236985 | F37: emails | G37: false | H37: 18.986495 | I37: emails | J37: false | K37: 8.937841 | L37: order | M37: false | N37: 58.912523 | O37: a7 | P37: false | Q37: 25.273387 | R37: I cant be sure | S37: true | T37: CPEE | U37: Get Sun Data | V37: simple | W37: 46.794712 | X37: date | Y37: false | Z37: 11.783837 | AA37: date | AB37: true | AC37: 6.912416 | AD37: sunrise,sunset | AE37: true | AF37: 67.486395 | AG37: a2,a3 | AH37: false | AI37: 36.246879 | AJ37: Yes | AK37: true | AL37: Confirm Coffee Preferences | AM37: Get Sun Data | AN37: simple | AO37: 39.158355 | AP37: -2 | AQ37: -2 | AS37: =IF(AND(G37="true",J37="true",M37="true",P37="true",S37="true"),"true","false") -> false | AT37: =IF(AND(Y37="true",AB37="true",AE37="true",AH37="true",AK37="true"),"true","false") -> false
A38: 419233e8-17be-460a-a46c-d0319ee260f7 | B38: BPMN | C38: Confirm Coffee Preferences | D38: simple | E38: 39.67438 | F38: items,order | G38: true | H38: 16.644866 | I38: items,order | J38: false | K38: 2.532538 | L38: order | M38: false | N38: 23.330567 | O38: a1,a4 | P38: false | Q38: 13.25581 | R38: No | S38: false | T38: CPEE | U38: Get Sun Data | V38: simple | W38: 23.886964 | X38: date,hour,sunrise,sunset | Y38: false | Z38: 0.522696 | AB38: false | AC38: 7.77848 | AD38: sunrise,sunset | AE38: true | AF38: 26.63 | AG38: a2,a5,a6 | AH38: true | AI38: 9.754909 | AJ38: Yes | AK38: true | AL38: Confirm Coffee Preferences | AM38: Get Sun Data | AN38: simple | AO38: 38.839503 | AP38: 2 | AQ38: 1 | AR38: Layout of CPEE BPMN | AS38: =IF(AND(G38="true",J38="true",M38="true",P38="true",S38="true"),"true","false") -> false | AT38: =IF(AND(Y38="true",AB38="true",AE38="true",AH38="true",AK38="true"),"true","false") -> false
A39: 4e624349-7010-4b12-883c-52ca95cfdfff | B39: BPMN | C39: Confirm Coffee Preferences | D39: simple | E39: 17.226584 | F39: items,order | G39: true | H39: 12.378849 | I39: order | J39: true | K39: 6.84197 | L39: items,order | M39: true | N39: 20.344006 | O39: a1,a4,a7 | P39: true | Q39: 34.46348 | R39: Yes | S39: false | T39: CPEE | U39: Get Sun Data | V39: simple | W39: 17.315848 | X39: date,sunrise,sunset | Y39: true | Z39: 55.668469 | AA39: sunrise,sunset | AB39: false | AC39: 7.2913 | AD39: date | AE39: false | AF39: 32.524631 | AG39: a2,a3,a5,a6 | AH39: false | AI39: 9.924456 | AJ39: Yes | AK39: true | AL39: Confirm Coffee Preferences | AM39: Get Sun Data | AN39: simple | AO39: 47.133769 | AP39: 2 | AQ39: 1 | AR39: Defining what "Part of a condition branch" means -> inside the condition itself or just part of the branch from a yes or no...? | AS39: =IF(AND(G39="true",J39="true",M39="true",P39="true",S39="true"),"true","false") -> false | AT39: =IF(AND(Y39="true",AB39="true",AE39="true",AH39="true",AK39="true"),"true","false") -> false
A40: 4e8c2f3d-caaf-4bfd-a0dd-45768e71dec9 | B40: BPMN | C40: Get Sun Data | D40: simple | E40: 16.989748 | F40: sunrise,sunset | G40: false | H40: 46.414634 | I40: date | J40: true | K40: 181.52444 | L40: sunrise,sunset | M40: true | N40: 38.76002 | O40: a2,a5,a6,a7 | P40: false | Q40: 31.450939 | R40: Yes | S40: false | T40: CPEE | U40: Confirm Coffee Preferences | V40: simple | W40: 78.89579 | X40: order | Y40: false | Z40: 9.23341 | AA40: items,order | AB40: false | AC40: 35.743651 | AD40: items,order | AE40: true | AF40: 30.751354 | AG40: a1,a4,a7 | AH40: true | AI40: 41.750863 | AJ40: Yes | AK40: false | AL40: Get Sun Data | AM40: Confirm Coffee Preferences | AN40: simple | AO40: 29.504191 | AP40: 0 | AQ40: -1 | AS40: =IF(AND(G40="true",J40="true",M40="true",P40="true",S40="true"),"true","false") -> false | AT40: =IF(AND(Y40="true",AB40="true",AE40="true",AH40="true",AK40="true"),"true","false") -> false
...

Sheet Medium
A1: 0107564a-165b-4c30-8e9c-7411e4ce2f81 | B1: BPMN | C1: Get Delays | D1: medium | E1: 26.49583 | F1: delay,line,lineID,stops | G1: true | H1: 19.796354 | I1: delay,line,lineID,stops | J1: true | K1: 4.119664 | L1: delay | M1: true | N1: 32.818027 | O1: a6,a8,a9 | P1: true | Q1: 21.601468 | R1: I cant be sure | S1: true | T1: CPEE | U1: Create Program | V1: medium | W1: 139.8721 | Y1: false | Z1: 0.471163 | AB1: false | AC1: 0.405355 | AE1: false | AF1: 1.133862 | AH1: false | AI1: 0.989791 | AK1: false | AL1: Get Delays | AM1: Create Program | AN1: medium | AO1: 2.190479 | AS1: =IF(AND(G1="true",J1="true",M1="true",P1="true",S1="true"),"true","false") -> true | AT1: =IF(AND(Y1="true",AB1="true",AE1="true",AH1="true",AK1="true"),"true","false") -> false
A2: 03c9e98d-f65f-4415-b447-91d18e8f6765 | B2: BPMN | C2: Get Delays | D2: medium | E2: 41.611119 | F2: delay,line,lineID,stops | G2: true | H2: 23.1904 | I2: delay,line,lineID,stops | J2: true | K2: 6.939846 | L2: delay | M2: true | N2: 25.27968 | O2: a6,a8,a9 | P2: true | Q2: 59.363228 | R2: I cant be sure | S2: true | T2: CPEE | U2: Create Program | V2: medium | W2: 36.876977 | X2: program,program_params,program_patterns,program_url | Y2: true | Z2: 10.003089 | AA2: program_params,program_patterns,program_url | AB2: true | AC2: 6.311144 | AD2: program | AE2: true | AF2: 29.270035 | AG2: a1,a2 | AH2: true | AI2: 55.729473 | AJ2: No | AK2: true | AL2: Get Delays | AM2: Create Program | AN2: medium | AO2: 18.994357 | AP2: 1 | AQ2: -1 | AS2: =IF(AND(G2="true",J2="true",M2="true",P2="true",S2="true"),"true","false") -> true | AT2: =IF(AND(Y2="true",AB2="true",AE2="true",AH2="true",AK2="true"),"true","false") -> true
A3: 0442f902-150d-4932-b671-f598ed4471df | B3: BPMN | C3: Create Program | D3: medium | E3: 25.683011 | F3: program,program_params,program_patterns,program_url | G3: true | H3: 9.688338 | I3: program_params,program_patterns,program_url | J3: true | K3: 4.43215 | L3: program | M3: true | N3: 56.2497 | O3: a1,a2 | P3: true | Q3: 15.798803 | R3: No | S3: false | T3: CPEE | U3: Get Delays | V3: medium | W3: 18.345308 | X3: delay,line,lineID,stops | Y3: true | Z3: 21.597163 | AA3: line,lineID,stops | AB3: false | AC3: 2.769705 | AD3: delay | AE3: true | AF3: 30.265077 | AG3: a6,a8,a9 | AH3: true | AI3: 13.626828 | AJ3: Yes | AK3: false | AL3: Create Program | AM3: Get Delays | AN3: medium | AO3: 6.650006 | AP3: -1 | AQ3: 1 | AS3: =IF(AND(G3="true",J3="true",M3="true",P3="true",S3="true"),"true","false") -> false | AT3: =IF(AND(Y3="true",AB3="true",AE3="true",AH3="true",AK3="true"),"true","false") -> false
A4: 05174b5e-6a0d-4027-a26a-f043ae9ab5a4 | B4: BPMN | C4: Create Program | D4: medium | E4: 51.223671 | F4: program,program_params,program_patterns,program_url | G4: true | H4: 20.335289 | I4: program_params,program_patterns,program_url | J4: true | K4: 4.848473 | L4: program | M4: true | N4: 17.931235 | O4: a1,a2 | P4: true | Q4: 8.086924 | R4: No | S4: false | T4: CPEE | U4: Get Delays | V4: medium | W4: 81.343317 | X4: delay,line,lineID,stops | Y4: true | Z4: 40.433481 | AA4: line,lineID,stops | AB4: false | AC4: 8.386873 | AE4: false | AF4: 44.244115 | AG4: a9 | AH4: false | AI4: 22.235637 | AJ4: I cant be sure | AK4: false | AL4: Create Program | AM4: Get Delays | AN4: medium | AO4: 10.474041 | AP4: 2 | AQ4: 1 | AS4: =IF(AND(G4="true",J4="true",M4="true",P4="true",S4="true"),"true","false") -> false | AT4: =IF(AND(Y4="true",AB4="true",AE4="true",AH4="true",AK4="true"),"true","false") -> false
A5: 076fd317-0638-48bd-8111-3fb2df39c131 | B5: BPMN | C5: Create Program | D5: medium | E5: 15.990828 | F5: program,program_params,program_patterns,program_url | G5: true | H5: 9.860478 | I5: program_params,program_patterns,program_url | J5: true | K5: 5.718652 | L5: program | M5: true | N5: 14.679421 | O5: a1,a2 | P5: true | Q5: 16.100797 | R5: No | S5: false | T5: CPEE | U5: Get Delays | V5: medium | W5: 20.495565 | X5: delay,line,lineID,stops | Y5: true | Z5: 15.903369 | AA5: delay,line,lineID,stops | AB5: true | AC5: 5.884284 | AD5: delay | AE5: true | AF5: 16.12294 | AG5: a6,a8,a9 | AH5: true | AI5: 9.836343 | AJ5: No | AK5: true | AL5: Create Program | AM5: Get Delays | AN5: medium | AO5: 5.861895 | AP5: 1 | AQ5: 1 | AS5: =IF(AND(G5="true",J5="true",M5="true",P5="true",S5="true"),"true","false") -> false | AT5: =IF(AND(Y5="true",AB5="true",AE5="true",AH5="true",AK5="true"),"true","false") -> true
A6: 10546761-dc0a-4e65-a46d-1123d21ae2d8 | B6: BPMN | C6: Get Delays | D6: medium | E6: 43.239081 | F6: delay,line,lineID,stops | G6: true | H6: 14.190743 | I6: delay,line,lineID,stops | J6: true | K6: 5.877469 | L6: delay | M6: true | N6: 20.597633 | O6: a6,a8,a9 | P6: true | Q6: 19.01184 | R6: I cant be sure | S6: true | T6: CPEE | U6: Create Program | V6: medium | W6: 21.340711 | X6: program,program_params,program_patterns,program_url | Y6: true | Z6: 13.120294 | AA6: program_params,program_patterns,program_url | AB6: true | AC6: 3.451552 | AD6: program | AE6: true | AF6: 32.57386 | AG6: a1,a2 | AH6: true | AI6: 16.488232 | AJ6: No | AK6: true | AL6: Get Delays | AM6: Create Program | AN6: medium | AO6: 37.274824 | AP6: 1 | AQ6: 1 | AR6: tradidional bpmn makes it hardes to view object connections compared to cpee | AS6: =IF(AND(G6="true",J6="true",M6="true",P6="true",S6="true"),"true","false") -> true | AT6: =IF(AND(Y6="true",AB6="true",AE6="true",AH6="true",AK6="true"),"true","false") -> true
A7: 14e40cad-de2a-46a4-bc62-7b3f969ecc76 | B7: BPMN | C7: Create Program | D7: medium | E7: 23.379023 | F7: program,program_params,program_patterns,program_url | G7: true | H7: 10.680519 | I7: program_params,program_patterns,program_url | J7: true | K7: 7.368253 | L7: program | M7: true | N7: 30.375706 | O7: a1,a2 | P7: true | Q7: 13.760426 | R7: Yes | S7: false | T7: CPEE | U7: Get Delays | V7: medium | W7: 15.195993 | X7: delay,line,lineID,stops | Y7: true | Z7: 21.040374 | AA7: delay,line,lineID,stops | AB7: true | AC7: 8.988676 | AD7: delay | AE7: true | AF7: 32.411963 | AG7: a6,a8,a9 | AH7: true | AI7: 7.14905 | AJ7: Yes | AK7: false | AL7: Create Program | AM7: Get Delays | AN7: medium | AO7: 3.843211 | AP7: 0 | AQ7: 0 | AS7: =IF(AND(G7="true",J7="true",M7="true",P7="true",S7="true"),"true","false") -> false | AT7: =IF(AND(Y7="true",AB7="true",AE7="true",AH7="true",AK7="true"),"true","false") -> false
A8: 167b5fc1-ac1a-4234-b246-6b4df7b175a7 | B8: BPMN | C8: Create Program | D8: medium | E8: 31.357183 | F8: program,program_params,program_patterns,program_url | G8: true | H8: 10.918233 | I8: program_params,program_patterns,program_url | J8: true | K8: 7.05061 | L8: program | M8: true | N8: 32.787219 | O8: a1,a2 | P8: true | Q8: 18.518131 | R8: No | S8: false | T8: CPEE | U8: Get Delays | V8: medium | W8: 37.088292 | X8: delay,line,lineID,stops | Y8: true | Z8: 51.654746 | AA8: delay | AB8: false | AC8: 9.382521 | AD8: line,lineID,stops | AE8: false | AF8: 16.062564 | AG8: a6,a8,a9 | AH8: true | AI8: 4.224075 | AJ8: No | AK8: true | AL8: Create Program | AM8: Get Delays | AN8: medium | AO8: 39.508578 | AP8: 1 | AQ8: 1 | AR8: keeping read and write apart in CPEE BPMN | AS8: =IF(AND(G8="true",J8="true",M8="true",P8="true",S8="true"),"true","false") -> false | AT8: =IF(AND(Y8="true",AB8="true",AE8="true",AH8="true",AK8="true"),"true","false") -> false
A9: 16db2a1a-7389-46ce-86e1-fbd3c924bfd8 | B9: BPMN | C9: Get Delays | D9: medium | E9: 22.462917 | F9: delay,line,lineID,stops | G9: true | H9: 20.046525 | I9: delay,line,lineID,stops | J9: true | K9: 5.25544 | L9: delay | M9: true | N9: 15.735987 | O9: a6,a8,a9 | P9: true | Q9: 11.31418 | R9: I cant be sure | S9: true | T9: CPEE | U9: Create Program | V9: medium | W9: 14.482483 | X9: program,program_params,program_patterns,program_url | Y9: true | Z9: 7.275683 | AA9: program | AB9: false | AC9: 6.493524 | AD9: program_params,program_patterns,program_url | AE9: false | AF9: 39.376643 | AG9: a1,a2 | AH9: true | AI9: 7.855114 | AJ9: Yes | AK9: false | AL9: Get Delays | AM9: Create Program | AN9: medium | AO9: 7.500933 | AP9: -1 | AQ9: 0 | AS9: =IF(AND(G9="true",J9="true",M9="true",P9="true",S9="true"),"true","false") -> true | AT9: =IF(AND(Y9="true",AB9="true",AE9="true",AH9="true",AK9="true"),"true","false") -> false
A10: 18b719f7-3652-4ab6-8ef7-6bcda80ba259 | B10: BPMN | C10: Create Program | D10: medium | E10: 18.578594 | F10: program,program_params,program_patterns,program_url | G10: true | H10: 17.444745 | I10: program_params,program_patterns,program_url | J10: true | K10: 2.14167 | L10: program | M10: true | N10: 20.314361 | O10: a1,a2 | P10: true | Q10: 29.690455 | R10: No | S10: false | T10: CPEE | U10: Get Delays | V10: medium | W10: 57.525618 | X10: delay,line,lineID,stops | Y10: true | Z10: 10.095247 | AA10: line,lineID,stops | AB10: false | AC10: 17.914451 | AD10: delay | AE10: true | AF10: 23.555412 | AG10: a6,a8,a9 | AH10: true | AI10: 28.688243 | AJ10: Yes | AK10: false | AL10: Create Program | AM10: Get Delays | AN10: medium | AO10: 7.624775 | AP10: 1 | AQ10: 1 | AS10: =IF(AND(G10="true",J10="true",M10="true",P10="true",S10="true"),"true","false") -> false | AT10: =IF(AND(Y10="true",AB10="true",AE10="true",AH10="true",AK10="true"),"true","false") -> false
A11: 18fcf92b-103c-4238-981c-1dcca8f55c9c | B11: BPMN | C11: Create Program | D11: medium | E11: 18.600328 | F11: program_params,program_patterns,program_url | G11: false | H11: 13.917748 | I11: program_params,program_patterns,program_url | J11: true | K11: 6.519898 | L11: program | M11: true | N11: 26.462681 | O11: a1,a2 | P11: true | Q11: 15.303386 | R11: No | S11: false | T11: CPEE | U11: Get Delays | V11: medium | W11: 13.341643 | X11: delay,line,lineID,stops | Y11: true | Z11: 10.901343 | AA11: line,lineID,stops | AB11: false | AC11: 10.777718 | AE11: false | AF11: 44.600837 | AG11: a8,a9 | AH11: false | AI11: 31.481471 | AJ11: No | AK11: true | AL11: Create Program | AM11: Get Delays | AN11: medium | AO11: 93.241386 | AP11: 0 | AQ11: 1 | AR11: Information about reading/writing from or to data objects are easier to get (more compact view with additional information if you hover over the objects) while using CPEE BPMN | AS11: =IF(AND(G11="true",J11="true",M11="true",P11="true",S11="true"),"true","false") -> false | AT11: =IF(AND(Y11="true",AB11="true",AE11="true",AH11="true",AK11="true"),"true","false") -> false
A12: 19d2fa7c-78bc-4ac2-89c0-485130dd3949 | B12: BPMN | C12: Create Program | D12: medium | E12: 32.35675 | F12: program,program_params,program_patterns,program_url | G12: true | H12: 27.526864 | I12: program_params,program_patterns,program_url | J12: true | K12: 4.374282 | L12: program | M12: true | N12: 18.906382 | O12: a1,a2 | P12: true | Q12: 11.950849 | R12: No | S12: false | T12: CPEE | U12: Get Delays | V12: medium | W12: 30.474758 | X12: delay,line,lineID,stops | Y12: true | Z12: 16.822454 | AA12: delay,line,lineID,stops | AB12: true | AC12: 4.681529 | AD12: delay | AE12: true | AF12: 24.347635 | AG12: a6,a8,a9 | AH12: true | AI12: 18.455294 | AJ12: Yes | AK12: false | AL12: Create Program | AM12: Get Delays | AN12: medium | AO12: 12.983451 | AP12: 1 | AQ12: 0 | AS12: =IF(AND(G12="true",J12="true",M12="true",P12="true",S12="true"),"true","false") -> false | AT12: =IF(AND(Y12="true",AB12="true",AE12="true",AH12="true",AK12="true"),"true","false") -> false
A13: 19d6031c-e0e7-42c2-b25b-a3c7ae02a1b2 | B13: BPMN | C13: Get Delays | D13: medium | E13: 16.110353 | F13: delay,line,lineID,stops | G13: true | H13: 12.108394 | I13: delay,line,lineID,stops | J13: true | K13: 5.364584 | L13: delay | M13: true | N13: 13.751907 | O13: a6,a8,a9 | P13: true | Q13: 9.467344 | R13: Yes | S13: false | T13: CPEE | U13: Create Program | V13: medium | W13: 20.180206 | X13: program,program_params,program_patterns,program_url | Y13: true | Z13: 10.06326 | AA13: program_params,program_patterns,program_url | AB13: true | AC13: 2.839556 | AD13: program | AE13: true | AF13: 17.67411 | AG13: a1,a2 | AH13: true | AI13: 4.350744 | AJ13: I cant be sure | AK13: false | AL13: Get Delays | AM13: Create Program | AN13: medium | AO13: 16.630468 | AP13: 1 | AQ13: -2 | AR13: i cant really read the second diagram | AS13: =IF(AND(G13="true",J13="true",M13="true",P13="true",S13="true"),"true","false") -> false | AT13: =IF(AND(Y13="true",AB13="true",AE13="true",AH13="true",AK13="true"),"true","false") -> false
A14: 1afbf9ee-80b9-4502-91b3-b16d835aaf39 | B14: BPMN | C14: Get Delays | D14: medium | E14: 28.854383 | F14: delay,line,lineID,stops | G14: true | H14: 11.899432 | I14: delay,line,lineID,stops | J14: true | K14: 5.197941 | L14: delay | M14: true | N14: 27.698164 | O14: a6,a8,a9 | P14: true | Q14: 11.644679 | R14: Yes | S14: false | T14: CPEE | U14: Create Program | V14: medium | W14: 32.389368 | X14: program,program_params,program_patterns,program_url | Y14: true | Z14: 16.572142 | AA14: program_params,program_patterns,program_url | AB14: true | AC14: 3.139401 | AD14: program | AE14: true | AF14: 30.576227 | AG14: a1,a2 | AH14: true | AI14: 11.546899 | AJ14: No | AK14: true | AL14: Get Delays | AM14: Create Program | AN14: medium | AO14: 10.729805 | AP14: 1 | AQ14: -1 | AS14: =IF(AND(G14="true",J14="true",M14="true",P14="true",S14="true"),"true","false") -> false | AT14: =IF(AND(Y14="true",AB14="true",AE14="true",AH14="true",AK14="true"),"true","false") -> true
A15: 1ce0dadb-b6cc-4be3-a9d7-115b74fe0c5c | B15: BPMN | C15: Get Delays | D15: medium | E15: 16.680694 | F15: delay,line,lineID,stops | G15: true | H15: 17.578306 | I15: delay,line,lineID,stops | J15: true | K15: 6.841447 | L15: delay | M15: true | N15: 26.336828 | O15: a6,a8,a9 | P15: true | Q15: 17.568093 | R15: Yes | S15: false | T15: CPEE | U15: Create Program | V15: medium | W15: 13.117887 | X15: program,program_params,program_patterns,program_url | Y15: true | Z15: 7.145594 | AA15: program_params,program_patterns,program_url | AB15: true | AC15: 4.738141 | AD15: program | AE15: true | AF15: 16.620975 | AG15: a1,a2 | AH15: true | AI15: 18.262874 | AJ15: No | AK15: true | AL15: Get Delays | AM15: Create Program | AN15: medium | AO15: 5.271617 | AP15: 0 | AQ15: 0 | AS15: =IF(AND(G15="true",J15="true",M15="true",P15="true",S15="true"),"true","false") -> false | AT15: =IF(AND(Y15="true",AB15="true",AE15="true",AH15="true",AK15="true"),"true","false") -> true
A16: 1d0f0221-6218-49a7-bb77-b16add35493c | B16: BPMN | C16: Create Program | D16: medium | E16: 11.725645 | F16: program,program_params,program_patterns,program_url | G16: true | H16: 9.114169 | I16: program_params,program_patterns,program_url | J16: true | K16: 6.603715 | L16: program | M16: true | N16: 17.160453 | O16: a1,a2 | P16: true | Q16: 13.761982 | R16: No | S16: false | T16: CPEE | U16: Get Delays | V16: medium | W16: 16.757507 | X16: delay,line,lineID,stops | Y16: true | Z16: 24.414483 | AA16: line,lineID,stopcoords,stops | AB16: false | AC16: 9.332568 | AD16: delay | AE16: true | AF16: 23.547241 | AG16: a1,a6,a7,a8,a9 | AH16: false | AI16: 15.185542 | AJ16: Yes | AK16: false | AL16: Create Program | AM16: Get Delays | AN16: medium | AO16: 127.7154 | AP16: 0 | AQ16: 1 | AR16: A definite upside of CPEE BPMN is the line-based presentation, which means that the appearance is consistent. One can imagine that with much experience, as long as CPEE BPMN can model a case as accurately as traditional BPMN, it can become much easier and efficient to work with CPEE, as a model will never look much too different from another, unlike with BPMN. The BPMN model was very cluttered with the message event at the beginning. | AS16: =IF(AND(G16="true",J16="true",M16="true",P16="true",S16="true"),"true","false") -> false | AT16: =IF(AND(Y16="true",AB16="true",AE16="true",AH16="true",AK16="true"),"true","false") -> false
A17: 1fcbb794-a8d6-458b-badd-f0d90dbbc3ce | B17: BPMN | C17: Get Delays | D17: medium | E17: 35.150485 | F17: delay,line,lineID,stops | G17: true | H17: 42.378009 | I17: delay,line,lineID,stops | J17: true | K17: 10.573 | L17: delay | M17: true | N17: 78.450568 | O17: a6,a8,a9 | P17: true | Q17: 3.432378 | R17: Yes | S17: false | T17: CPEE | U17: Create Program | V17: medium | W17: 48.722237 | X17: program,program_params,program_patterns,program_url | Y17: true | Z17: 14.038167 | AA17: program_params,program_patterns,program_url | AB17: true | AC17: 5.684687 | AD17: program | AE17: true | AF17: 16.24396 | AG17: a1,a2 | AH17: true | AI17: 4.199043 | AJ17: Yes | AK17: false | AL17: Get Delays | AM17: Create Program | AN17: medium | AO17: 7.492957 | AP17: 0 | AQ17: 1 | AS17: =IF(AND(G17="true",J17="true",M17="true",P17="true",S17="true"),"true","false") -> false | AT17: =IF(AND(Y17="true",AB17="true",AE17="true",AH17="true",AK17="true"),"true","false") -> false
A18: 201405ab-b454-4221-8932-2add933a8217 | B18: BPMN | C18: Create Program | D18: medium | E18: 16.268111 | F18: program,program_params,program_patterns,program_url | G18: true | H18: 8.984717 | I18: program_params,program_patterns,program_url | J18: true | K18: 1.890651 | L18: program | M18: true | N18: 29.194752 | O18: a1,a2 | P18: true | Q18: 12.025113 | R18: No | S18: false | T18: CPEE | U18: Get Delays | V18: medium | W18: 9.83413 | X18: delay,stops | Y18: false | Z18: 2.400529 | AA18: delay,stopnames,stops | AB18: false | AC18: 1.743623 | AD18: delay,stopnames,stops | AE18: false | AF18: 2.141219 | AG18: a4,a6 | AH18: false | AI18: 1.626317 | AJ18: Yes | AK18: false | AL18: Create Program | AM18: Get Delays | AN18: medium | AO18: 2.743462 | AP18: 1 | AQ18: 1 | AS18: =IF(AND(G18="true",J18="true",M18="true",P18="true",S18="true"),"true","false") -> false | AT18: =IF(AND(Y18="true",AB18="true",AE18="true",AH18="true",AK18="true"),"true","false") -> false
A19: 21d4e75b-2ace-4387-ac23-31b054fc5c80 | B19: BPMN | C19: Get Delays | D19: medium | E19: 61.13444 | F19: delay,line,lineID,stops | G19: true | H19: 162.38736 | I19: delay,line,lineID,stops | J19: true | K19: 22.450468 | L19: delay | M19: true | N19: 40.898627 | O19: a6,a8,a9 | P19: true | Q19: 114.68695 | R19: No | S19: false | T19: CPEE | U19: Create Program | V19: medium | W19: 18.974182 | Y19: false | Z19: 0.474213 | AB19: false | AC19: 0.416839 | AE19: false | AF19: 2.420661 | AH19: false | AI19: 1.851179 | AJ19: I cant be sure | AK19: false | AL19: Get Delays | AM19: Create Program | AN19: medium | AO19: 12.697297 | AP19: -1 | AQ19: 2 | AS19: =IF(AND(G19="true",J19="true",M19="true",P19="true",S19="true"),"true","false") -> false | AT19: =IF(AND(Y19="true",AB19="true",AE19="true",AH19="true",AK19="true"),"true","false") -> false
A20: 22513e52-594a-4580-ae50-eb03d85a4230 | B20: BPMN | C20: Get Delays | D20: medium | E20: 51.046268 | F20: delay,line,lineID,stops | G20: true | H20: 24.336941 | I20: delay,line,lineID,stops | J20: true | K20: 4.37023 | L20: delay | M20: true | N20: 22.30559 | O20: a6,a8,a9 | P20: true | Q20: 10.989433 | R20: Yes | S20: false | T20: CPEE | U20: Create Program | V20: medium | W20: 78.261245 | X20: program_params,program_patterns,program_url | Y20: false | Z20: 8.898263 | AA20: program_params,program_patterns,program_url | AB20: true | AC20: 3.082355 | AD20: program,qr | AE20: false | AF20: 14.888143 | AG20: a7,a8 | AH20: false | AI20: 5.051052 | AJ20: I cant be sure | AK20: false | AL20: Get Delays | AM20: Create Program | AN20: medium | AO20: 13.553619 | AP20: 1 | AQ20: -2 | AS20: =IF(AND(G20="true",J20="true",M20="true",P20="true",S20="true"),"true","false") -> false | AT20: =IF(AND(Y20="true",AB20="true",AE20="true",AH20="true",AK20="true"),"true","false") -> false
A21: 25d1dfbf-09b7-45ef-98f6-9839232ac242 | B21: BPMN | C21: Create Program | D21: medium | E21: 35.728439 | F21: program,program_params,program_patterns,program_url | G21: true | H21: 19.930775 | I21: program_params,program_patterns,program_url | J21: true | K21: 10.37269 | L21: program | M21: true | N21: 26.79069 | O21: a1,a2,a8 | P21: false | Q21: 14.929972 | R21: Yes | S21: false | T21: CPEE | U21: Get Delays | V21: medium | W21: 29.514342 | X21: delay,line,lineID,stops | Y21: true | Z21: 42.05845 | AA21: delay,line,lineID,stops | AB21: true | AC21: 11.65914 | AD21: delay | AE21: true | AF21: 22.623832 | AG21: a1,a6,a8,a9 | AH21: false | AI21: 15.914162 | AJ21: Yes | AK21: false | AL21: Create Program | AM21: Get Delays | AN21: medium | AO21: 59.027002 | AP21: 1 | AQ21: 1 | AR21: Ãbersichtlichkeit, remembering what is read and what is written (as in symbols), what is included in condition statements | AS21: =IF(AND(G21="true",J21="true",M21="true",P21="true",S21="true"),"true","false") -> false | AT21: =IF(AND(Y21="true",AB21="true",AE21="true",AH21="true",AK21="true"),"true","false") -> false
A22: 28fef484-a729-49ab-9fc7-ea1199c8cadf | B22: BPMN | C22: Create Program | D22: medium | E22: 26.405776 | F22: program,program_params,program_patterns,program_url | G22: true | H22: 9.110928 | I22: program_params,program_patterns,program_url | J22: true | K22: 4.772995 | L22: program | M22: true | N22: 26.814135 | O22: a1,a2 | P22: true | Q22: 6.497594 | R22: No | S22: false | T22: CPEE | U22: Get Delays | V22: medium | W22: 19.92331 | X22: delay,line,lineID,stops | Y22: true | Z22: 21.373996 | AA22: delay,line,lineID,stops | AB22: true | AC22: 6.757987 | AD22: delay | AE22: true | AF22: 21.649592 | AG22: a6,a8,a9 | AH22: true | AI22: 56.731834 | AJ22: No | AK22: true | AL22: Create Program | AM22: Get Delays | AN22: medium | AO22: 3.111102 | AP22: 1 | AQ22: 1 | AS22: =IF(AND(G22="true",J22="true",M22="true",P22="true",S22="true"),"true","false") -> false | AT22: =IF(AND(Y22="true",AB22="true",AE22="true",AH22="true",AK22="true"),"true","false") -> true
A23: 315b52ea-3bd8-4270-a304-5e9cdc831a60 | B23: BPMN | C23: Create Program | D23: medium | E23: 20.602141 | F23: program | G23: false | H23: 13.073506 | I23: program_params,program_patterns,program_url | J23: true | K23: 6.268215 | L23: program | M23: true | N23: 10.118696 | O23: a1,a2 | P23: true | Q23: 7.977425 | R23: Yes | S23: false | T23: CPEE | U23: Get Delays | V23: medium | W23: 17.00434 | X23: delay | Y23: false | Z23: 17.470199 | AA23: stopcoords,stops | AB23: false | AC23: 3.828786 | AD23: delay | AE23: true | AF23: 4.747892 | AG23: a1 | AH23: false | AI23: 3.456584 | AJ23: No | AK23: true | AL23: Create Program | AM23: Get Delays | AN23: medium | AO23: 10.036402 | AP23: 1 | AQ23: -2 | AR23: IT IS NOT LOADING | AS23: =IF(AND(G23="true",J23="true",M23="true",P23="true",S23="true"),"true","false") -> false | AT23: =IF(AND(Y23="true",AB23="true",AE23="true",AH23="true",AK23="true"),"true","false") -> false
